Workbook

Sheet Paste DP
A1: Created by | B1: Created Date | C1: Last Updated | D1: Form ID | E1: Form Version | F1: Form Number | G1: Workflow Column | H1: Date | I1: Company Name | J1: Hours - Project | K1: Hours - Activity | L1: Hours - Start Time | M1: Hours - End Time | N1: Hours - Ordinary Hours | O1: Hours - Comments | P1: Hours Summary - Total Ordinary Hours | Q1: Hours Summary - Project Hours Summary | R1: Employee Signoff | S1: Date Signed | T1: Time Signed | U1: Supervisor Signature | V1: Date Signed | W1: Time Signed
A2: Sean Gray | B2: 46191 | C2: 46192 | D2: 6a3374bf07310476663716f3 | E2: V1.1 | F2: 5863 | G2: Complete | H2: 46191 | I2: Harwyn | J2: HWYN2608 Emmaus (2 Mega & Classroom) | K2: 00408 - Structural Steel: Level bases and straighten structural steel | L2: 0.25 | M2: 0.60555556 | N2: 8.53 | O2: - | P2: 8.03 | Q2: HWYN2608 Emmaus (2 Mega & Classroom) | R2: Signed - Sean Gray | S2: 46191 | T2: 0.60587963 | U2: Signed - Dan Guille | V2: 46192 | W2: 0.37046296
A3: Martin Fischer | B3: 46191 | C3: 46192 | D3: 6a33011e4e6562db34b156b9 | E3: V1.1 | F3: 5862 | G3: Complete | H3: 46191 | I3: Harwyn | J3: HWYN2608 Emmaus (2 Mega & Classroom) | K3: 00408 - Structural Steel: Level bases and straighten structural steel | L3: 0.26180556 | M3: 0.60416667 | N3: 8.22 | O3: - | P3: 7.72 | Q3: HWYN2608 Emmaus (2 Mega & Classroom) | R3: Signed - Martin Fischer | S3: 46191 | T3: 0.60435185 | U3: Signed - Dan Guille | V3: 46192 | W3: 0.37034722
A4: Lyric Kereopa | B4: 46191 | C4: 46191 | D4: 6a32b6dd1623ba28abbe6c65 | E4: V1.1 | F4: 5857 | G4: Complete | H4: 46190 | I4: Harwyn | J4: HWYN2608 Emmaus (2 Mega & Classroom) | K4: 00824 - Internal Linings/ Finishes: Install Cement Sheet | L4: 0.25 | M4: 0.60416667 | N4: 8.5 | O4: - | P4: 8 | Q4: HWYN2608 Emmaus (2 Mega & Classroom) | R4: Signed - Lyric Kereopa | S4: 46191 | T4: 0.043668981 | U4: Signed - Dan Guille | V4: 46191 | W4: 0.32871528
A5: Martin Fischer | B5: 46190 | C5: 46191 | D5: 6a31a99025e7ecafdf9bfeae | E5: V1.1 | F5: 5859 | G5: Complete | H5: 46190 | I5: Harwyn | J5: HWYN2608 Emmaus (2 Mega & Classroom) | K5: 00503 - Framing: Frame Installation | L5: 0.24652778 | M5: 0.60416667 | N5: 8.58 | O5: - | P5: 8.08 | Q5: HWYN2608 Emmaus (2 Mega & Classroom) | R5: Signed - Martin Fischer | S5: 46191 | T5: 0.24369213 | U5: Signed - Dan Guille | V5: 46191 | W5: 0.32797454
A6: Sean Gray | B6: 46190 | C6: 46191 | D6: 6a31a8874c2f7f5c5d91841f | E6: V1.1 | F6: 5861 | G6: Complete | H6: 46190 | I6: Harwyn | J6: HWYN2608 Emmaus (2 Mega & Classroom) | K6: 00408 - Structural Steel: Level bases and straighten structural steel | L6: 0.24722222 | M6: 0.60416667 | N6: 8.57 | O6: - | P6: 8.07 | Q6: HWYN2608 Emmaus (2 Mega & Classroom) | R6: Signed - Sean Gray | S6: 46191 | T6: 0.38309028 | U6: Signed - Dan Guille | V6: 46191 | W6: 0.38381944
A7: Martin Fischer | B7: 46190 | C7: 46190 | D7: 6a31a8700d41878708d7f9df | E7: V1.1 | F7: 5853 | G7: Complete | H7: 46189 | I7: Harwyn | J7: HWYN2608 Emmaus (2 Mega & Classroom) | K7: 00606 - Floor Structure: Install Structflor | L7: 0.25 | M7: 0.375 | N7: 3 | O7: - | P7: 8 | Q7: HWYN2608 Emmaus (2 Mega & Classroom) | R7: Signed - Martin Fischer | S7: 46190 | T7: 0.24271991 | U7: Signed - Dan Guille | V7: 46190 | W7: 0.24847222
A8: Martin Fischer | B8: 46190 | C8: 46190 | D8: 6a31a8700d41878708d7f9df | E8: V1.1 | F8: 5853 | G8: Complete | H8: 46189 | I8: Harwyn | J8: HWYN2608 Emmaus (2 Mega & Classroom) | K8: 00503 - Framing: Frame Installation | L8: 0.375 | M8: 0.60416667 | N8: 5.5 | O8: -
A9: Sean Gray | B9: 46190 | C9: 46190 | D9: 6a31a8504c2f7f5c5d91841e | E9: V1.1 | F9: 5852 | G9: Complete | H9: 46189 | I9: Harwyn | J9: 00: Absent | K9: 00 - ABSENT | L9: 0.25 | M9: 0.5875 | N9: 8.1 | O9: SICK LEAVE | P9: 7.6 | Q9: 00: Absent | R9: Signed - Sean Gray | S9: 46190 | T9: 0.24171296 | U9: Signed - Dan Guille | V9: 46190 | W9: 0.24834491
A10: Lyric Kereopa | B10: 46191 | C10: 46191 | D10: 6a32b7271623ba28abbe6c66 | E10: V1.1 | F10: 5858 | G10: Complete | H10: 46188 | I10: Harwyn | J10: HWYN2608 Emmaus (2 Mega & Classroom) | K10: 00503 - Framing: Frame Installation | L10: 0.25 | M10: 0.60416667 | N10: 8.5 | O10: - | P10: 8 | Q10: HWYN2608 Emmaus (2 Mega & Classroom) | R10: Signed - Lyric Kereopa | S10: 46191 | T10: 0.044247685 | U10: Signed - Dan Guille | V10: 46191 | W10: 0.32922454
A11: Sean Gray | B11: 46190 | C11: 46190 | D11: 6a31a80d4c2f7f5c5d91841d | E11: V1.1 | F11: 5851 | G11: Complete | H11: 46188 | I11: Harwyn | J11: 00: Absent | K11: 00 - ABSENT | L11: 0.25 | M11: 0.5875 | N11: 8.1 | O11: SICK LEAVE | P11: 7.6 | Q11: 00: Absent | R11: Signed - Sean Gray | S11: 46190 | T11: 0.24116898 | U11: Signed - Dan Guille | V11: 46190 | W11: 0.24868056
A12: Lyric Kereopa | B12: 46188 | C12: 46189 | D12: 6a2fb82d4eb190af34a979fa | E12: V1.1 | F12: 5839 | G12: Complete | H12: 46188 | I12: Harwyn | J12: HWYN2608 Emmaus (2 Mega & Classroom) | K12: 00603 - Floor Structure: Install Kingspan (inc. cutting) | L12: 0.25 | M12: 0.60416667 | N12: 8.5 | O12: - | P12: 8 | Q12: HWYN2608 Emmaus (2 Mega & Classroom) | R12: Signed - Lyric Kereopa | S12: 46188 | T12: 0.77163194 | U12: Signed - Dan Guille | V12: 46189 | W12: 0.38986111
A13: Martin Fischer | B13: 46188 | C13: 46189 | D13: 6a2f78073d7da8fd10f6f032 | E13: V1.1 | F13: 5841 | G13: Complete | H13: 46188 | I13: Harwyn | J13: HWYN2608 Emmaus (2 Mega & Classroom) | K13: 00603 - Floor Structure: Install Kingspan (inc. cutting) | L13: 0.25 | M13: 0.60416667 | N13: 8.5 | O13: - | P13: 8 | Q13: HWYN2608 Emmaus (2 Mega & Classroom) | R13: Signed - Martin Fischer | S13: 46189 | T13: 0.25140046 | U13: Signed - Dan Guille | V13: 46189 | W13: 0.38976852
A14: Lyric Kereopa | B14: 46188 | C14: 46188 | D14: 6a2eff09a0de39b934aa5106 | E14: V1.1 | F14: 5838 | G14: Complete | H14: 46185 | I14: Harwyn | J14: HWYN2608 Emmaus (2 Mega & Classroom) | K14: 00606 - Floor Structure: Install Structflor | L14: 0.27083333 | M14: 0.60416667 | N14: 8 | O14: - | P14: 7.5 | Q14: HWYN2608 Emmaus (2 Mega & Classroom) | R14: Signed - Lyric Kereopa | S14: 46188 | T14: 0.22328704 | U14: Signed - Dan Guille | V14: 46188 | W14: 0.32755787
A15: Martin Fischer | B15: 46185 | C15: 46188 | D15: 6a2b146991650a34d76d9638 | E15: V1.1 | F15: 5832 | G15: Complete | H15: 46185 | I15: Harwyn | J15: HWYN2608 Emmaus (2 Mega & Classroom) | K15: 00606 - Floor Structure: Install Structflor | L15: 0.25 | M15: 0.60416667 | N15: 8.5 | O15: - | P15: 8 | Q15: HWYN2608 Emmaus (2 Mega & Classroom) | R15: Signed - Martin Fischer | S15: 46185 | T15: 0.60400463 | U15: Signed - Dan Guille | V15: 46188 | W15: 0.32688657
A16: Sean Gray | B16: 46185 | C16: 46188 | D16: 6a2b14029407e81dbbdd7d36 | E16: V1.1 | F16: 5835 | G16: Complete | H16: 46185 | I16: Harwyn | J16: HWYN2608 Emmaus (2 Mega & Classroom) | K16: 00606 - Floor Structure: Install Structflor | L16: 0.24652778 | M16: 0.60694444 | N16: 8.65 | O16: - | P16: 8.15 | Q16: HWYN2608 Emmaus (2 Mega & Classroom) | R16: Signed - Sean Gray | S16: 46185 | T16: 0.83416667 | U16: Signed - Dan Guille | V16: 46188 | W16: 0.32672454
A17: Lyric Kereopa | B17: 46184 | C17: 46185 | D17: 6a2a3d4e1dd258e284ff821d | E17: V1.1 | F17: 5826 | G17: Complete | H17: 46184 | I17: Harwyn | J17: HWYN2608 Emmaus (2 Mega & Classroom) | K17: 00606 - Floor Structure: Install Structflor | L17: 0.25 | M17: 0.60416667 | N17: 8.5 | O17: - | P17: 8 | Q17: HWYN2608 Emmaus (2 Mega & Classroom) | R17: Signed - Lyric Kereopa | S17: 46184 | T17: 0.61520833 | U17: Signed - Dan Guille | V17: 46185 | W17: 0.36666667
A18: Martin Fischer | B18: 46184 | C18: 46185 | D18: 6a2a39467560597d2c90b853 | E18: V1.1 | F18: 5824 | G18: Complete | H18: 46184 | I18: Harwyn | J18: HWYN2608 Emmaus (2 Mega & Classroom) | K18: 00606 - Floor Structure: Install Structflor | L18: 0.26944444 | M18: 0.60416667 | N18: 8.03 | O18: - | P18: 7.53 | Q18: HWYN2608 Emmaus (2 Mega & Classroom) | R18: Signed - Martin Fischer | S18: 46184 | T18: 0.603125 | U18: Signed - Dan Guille | V18: 46185 | W18: 0.36652778
A19: Sean Gray | B19: 46184 | C19: 46185 | D19: 6a29c2fcf05dce590426e2dc | E19: V1.1 | F19: 5825 | G19: Complete | H19: 46184 | I19: Harwyn | J19: HWYN2608 Emmaus (2 Mega & Classroom) | K19: 00606 - Floor Structure: Install Structflor | L19: 0.25 | M19: 0.61458333 | N19: 8.75 | O19: - | P19: 8.25 | Q19: HWYN2608 Emmaus (2 Mega & Classroom) | R19: Signed - Sean Gray | S19: 46184 | T19: 0.6144213 | U19: Signed - Dan Guille | V19: 46185 | W19: 0.36641204
A20: Lyric Kereopa | B20: 46183 | C20: 46184 | D20: 6a2940bfbe63cf6dc791d0ff | E20: V1.1 | F20: 5820 | G20: Complete | H20: 46183 | I20: Harwyn | J20: HWYN2608 Emmaus (2 Mega & Classroom) | K20: 00603 - Floor Structure: Install Kingspan (inc. cutting) | L20: 0.27083333 | M20: 0.60416667 | N20: 8 | O20: - | P20: 7.5 | Q20: HWYN2608 Emmaus (2 Mega & Classroom) | R20: Signed - Lyric Kereopa | S20: 46183 | T20: 0.86694444 | U20: Signed - Dan Guille | V20: 46184 | W20: 0.35096065
... A24: Martin Fischer | B24: 46182 | C24: 46184 | D24: 6a27235e52bb8a71a31a61f6 | E24: V1.1 | F24: 5810 | G24: Complete | H24: 46182 | I24: Harwyn | J24: HWYN2608 Emmaus (2 Mega & Classroom) | K24: 00408 - Structural Steel: Level bases and straighten structural steel | L24: 0.26111111 | M24: 0.53472222 | N24: 6.57 | O24: - | P24: 7.6 | Q24: HWYN2608 Emmaus (2 Mega & Classroom) | R24: Signed - Martin Fischer | S24: 46183 | T24: 0.60108796 | U24: Signed - Dan Guille | V24: 46184 | W24: 0.35204861
A25: Martin Fischer | B25: 46182 | C25: 46184 | D25: 6a27235e52bb8a71a31a61f6 | E25: V1.1 | F25: 5810 | G25: Complete | H25: 46182 | I25: Harwyn | J25: 00: Absent | K25: 00 - ABSENT | L25: 0.53472222 | M25: 0.59861111 | N25: 1.53 | O25: Annual leave
A26: Sean Gray | B26: 46180 | C26: 46183 | D26: 6a2547b3a56602aeccf3bee2 | E26: V1.1 | F26: 5809 | G26: Complete | H26: 46182 | I26: Harwyn | J26: HWYN2608 Emmaus (2 Mega & Classroom) | K26: 00408 - Structural Steel: Level bases and straighten structural steel | L26: 0.25 | M26: 0.60416667 | N26: 8.5 | O26: - | P26: 8 | Q26: HWYN2608 Emmaus (2 Mega & Classroom) | R26: Signed - Sean Gray | S26: 46183 | T26: 0.25255787 | U26: Signed - Dan Guille | V26: 46183 | W26: 0.2899537
A27: Lyric Kereopa | B27: 46183 | C27: 46184 | D27: 6a294003be63cf6dc791d0fd | E27: V1.1 | F27: 5818 | G27: Complete | H27: 46178 | I27: Harwyn | J27: HWYN2608 Emmaus (2 Mega & Classroom) | K27: 00407 - Structural Steel: Paint Base Labour | L27: 0.29166667 | M27: 0.64583333 | N27: 8.5 | O27: - | P27: 8 | Q27: HWYN2608 Emmaus (2 Mega & Classroom) | R27: Signed - Lyric Kereopa | S27: 46183 | T27: 0.86498843 | U27: Signed - Dan Guille | V27: 46184 | W27: 0.35271991
A28: Sean Gray | B28: 46178 | C28: 46182 | D28: 6a2253cbf0b5a748bfa590bf | E28: V1.1 | F28: 5801 | G28: Complete | H28: 46178 | I28: Harwyn | J28: HWYN0000 General Factory | K28: 00406 - Structural Steel: Structural Steel external coating paint | L28: 0.25 | M28: 0.6125 | N28: 8.7 | O28: Set out first part of the day | P28: 8.2 | Q28: HWYN0000 General Factory | R28: Signed - Sean Gray | S28: 46178 | T28: 0.6137037 | U28: Signed - Dan Guille | V28: 46182 | W28: 0.31697917
A29: Martin Fischer | B29: 46178 | C29: 46182 | D29: 6a2245649f51c84e2abf4012 | E29: V1.1 | F29: 5802 | G29: Complete | H29: 46178 | I29: Harwyn | J29: HWYN2608 Emmaus (2 Mega & Classroom) | K29: 00407 - Structural Steel: Paint Base Labour | L29: 0.25 | M29: 0.60416667 | N29: 8.5 | O29: - | P29: 8 | Q29: HWYN2608 Emmaus (2 Mega & Classroom) | R29: Signed - Martin Fischer | S29: 46178 | T29: 0.6569213 | U29: Signed - Dan Guille | V29: 46182 | W29: 0.31671296
A30: Lyric Kereopa | B30: 46183 | C30: 46184 | D30: 6a293f26be63cf6dc791d0fc | E30: V1.1 | F30: 5817 | G30: Complete | H30: 46177 | I30: Harwyn | J30: HWYN2608 Emmaus (2 Mega & Classroom) | K30: 01704 - Prep modules for Transport: Split pods and Transport Prep | L30: 0.29166667 | M30: 0.64583333 | N30: 8.5 | O30: - | P30: 8 | Q30: HWYN2608 Emmaus (2 Mega & Classroom) | R30: Signed - Lyric Kereopa | S30: 46183 | T30: 0.86398148 | U30: Signed - Dan Guille | V30: 46184 | W30: 0.35293981
A31: Martin Fischer | B31: 46178 | C31: 46182 | D31: 6a2244929f51c84e2abf4011 | E31: V1.1 | F31: 5800 | G31: Complete | H31: 46177 | I31: Harwyn | J31: HWYN2608 Emmaus (2 Mega & Classroom) | K31: 00407 - Structural Steel: Paint Base Labour | L31: 0.25 | M31: 0.60416667 | N31: 8.5 | O31: - | P31: 8 | Q31: HWYN2608 Emmaus (2 Mega & Classroom) | R31: Signed - Martin Fischer | S31: 46178 | T31: 0.56954861 | U31: Signed - Dan Guille | V31: 46182 | W31: 0.31711806
A32: Sean Gray | B32: 46177 | C32: 46178 | D32: 6a210d2a323343d87aabff3b | E32: V1.1 | F32: 5798 | G32: Complete | H32: 46177 | I32: Harwyn | J32: HWYN0000 General Factory | K32: 01906 - Building Install: Onsite Commissioning Works | L32: 0.29166667 | M32: 0.64583333 | N32: 8.5 | O32: - | P32: 8 | Q32: HWYN0000 General Factory | R32: Signed - Sean Gray | S32: 46177 | T32: 0.64594907 | U32: Signed - Dan Guille | V32: 46178 | W32: 0.40725694
A33: Sean Gray | B33: 46177 | C33: 46178 | D33: 6a210cc2323343d87aabff3a | E33: V1.1 | F33: 5797 | G33: Complete | H33: 46176 | I33: Harwyn | J33: HWYN0000 General Factory | K33: 01906 - Building Install: Onsite Commissioning Works | L33: 0.25 | M33: 0.5875 | N33: 8.1 | O33: - | P33: 7.6 | Q33: HWYN0000 General Factory | R33: Signed - Sean Gray | S33: 46177 | T33: 0.64509259 | U33: Signed - Dan Guille | V33: 46178 | W33: 0.40802083
A34: Lyric Kereopa | B34: 46176 | C34: 46178 | D34: 6a1fcf90f205f35e5ed50992 | E34: V1.1 | F34: 5795 | G34: Complete | H34: 46176 | I34: Harwyn | J34: HWYN0000 General Factory | K34: 01906 - Building Install: Onsite Commissioning Works | L34: 0.29166667 | M34: 0.62916667 | N34: 8.1 | O34: - | P34: 7.6 | Q34: HWYN0000 General Factory | R34: Signed - Lyric Kereopa | S34: 46176 | T34: 0.70538194 | U34: Signed - Dan Guille | V34: 46178 | W34: 0.40787037
A35: Martin Fischer | B35: 46176 | C35: 46178 | D35: 6a1fb9dc6e176029cef4e76c | E35: V1.1 | F35: 5794 | G35: Complete | H35: 46176 | I35: Harwyn | J35: HWYN0000 General Factory | K35: 01907 - Building Install: On-site Clean | L35: 0.25 | M35: 0.5875 | N35: 8.1 | O35: - | P35: 7.6 | Q35: HWYN0000 General Factory | R35: Signed - Martin Fischer | S35: 46176 | T35: 0.64060185 | U35: Signed - Dan Guille | V35: 46178 | W35: 0.40775463
A36: Martin Fischer | B36: 46176 | C36: 46178 | D36: 6a1fb9aa6e176029cef4e76b | E36: V1.1 | F36: 5793 | G36: Complete | H36: 46175 | I36: Harwyn | J36: HWYN0000 General Factory | K36: 01907 - Building Install: On-site Clean | L36: 0.25 | M36: 0.58333333 | N36: 8 | O36: - | P36: 7.5 | Q36: HWYN0000 General Factory | R36: Signed - Martin Fischer | S36: 46176 | T36: 0.63981481 | U36: Signed - Dan Guille | V36: 46178 | W36: 0.40811343
A37: Sean Gray | B37: 46175 | C37: 46176 | D37: 6a1de58e0de43044904a14b2 | E37: V1.1 | F37: 5788 | G37: Complete | H37: 46175 | I37: Harwyn | J37: HWYN0000 General Factory | K37: 01907 - Building Install: On-site Clean | L37: 0.25 | M37: 0.58611111 | N37: 8.07 | O37: Misc works | P37: 7.57 | Q37: HWYN0000 General Factory | R37: Signed - Sean Gray | S37: 46175 | T37: 0.68511574 | U37: Signed - Dan Guille | V37: 46176 | W37: 0.40644676
... A45: Sean Gray | B45: 46168 | C45: 46169 | D45: 6a151f367418eb291604b501 | E45: V1.1 | F45: 5764 | G45: Complete | H45: 46168 | I45: Harwyn | J45: HWYN2535 Westbourne Grammar | K45: 01704 - Prep modules for Transport: Split pods and Transport Prep | L45: 0.25 | M45: 0.35416667 | N45: 2.5 | O45: - | P45: 8 | Q45: HWYN2535 Westbourne Grammar | R45: Signed - Sean Gray | S45: 46168 | T45: 0.60452546 | U45: Signed - Dan Guille | V45: 46169 | W45: 0.37496528
A46: Sean Gray | B46: 46168 | C46: 46169 | D46: 6a151f367418eb291604b501 | E46: V1.1 | F46: 5764 | G46: Complete | H46: 46168 | I46: Harwyn | J46: HWYN2608 Emmaus (2 Mega & Classroom) | K46: 01305 - Insulation: Insulation Installation | L46: 0.35416667 | M46: 0.45833333 | N46: 2.5 | O46: -
A47: Sean Gray | B47: 46168 | C47: 46169 | D47: 6a151f367418eb291604b501 | E47: V1.1 | F47: 5764 | G47: Complete | H47: 46168 | I47: Harwyn | J47: HWYN0000 General Factory | K47: 00845 - Internal Linings/ Finishes: Birch Ply Prep Work (not install) | L47: 0.45833333 | M47: 0.60416667 | N47: 3.5 | O47: -
A48: Martin Fischer | B48: 46168 | C48: 46169 | D48: 6a151f1a6cd7ab830a2273ad | E48: V1.1 | F48: 5763 | G48: Complete | H48: 46168 | I48: Harwyn | J48: HWYN2535 Westbourne Grammar | K48: 01704 - Prep modules for Transport: Split pods and Transport Prep | L48: 0.25 | M48: 0.35416667 | N48: 2.5 | O48: - | P48: 8 | Q48: HWYN2535 Westbourne Grammar | R48: Signed - Martin Fischer | S48: 46168 | T48: 0.6043287 | U48: Signed - Dan Guille | V48: 46169 | W48: 0.37484954
A49: Martin Fischer | B49: 46168 | C49: 46169 | D49: 6a151f1a6cd7ab830a2273ad | E49: V1.1 | F49: 5763 | G49: Complete | H49: 46168 | I49: Harwyn | J49: HWYN2608 Emmaus (2 Mega & Classroom) | K49: 01305 - Insulation: Insulation Installation | L49: 0.35416667 | M49: 0.45833333 | N49: 2.5 | O49: -
A50: Martin Fischer | B50: 46168 | C50: 46169 | D50: 6a151f1a6cd7ab830a2273ad | E50: V1.1 | F50: 5763 | G50: Complete | H50: 46168 | I50: Harwyn | J50: HWYN0000 General Factory | K50: 00845 - Internal Linings/ Finishes: Birch Ply Prep Work (not install) | L50: 0.45833333 | M50: 0.60416667 | N50: 3.5 | O50: -
...

Sheet BL
A1: {=_xlfn._xlws.FILTER('Paste DP'!F:F,'Paste DP'!F:F<>"")} -> Form Number | B1: AccountingSystemCode | C1: Companyname | D1: TimeCostDate | E1: JobNumber | F1: Trade | G1: CostCode | H1: ReferenceCode | I1: Description | J1: Hours | K1: Rate | L1: TaxCode | M1: total
A2: 5863 | B2: {=_xlfn.XLOOKUP(_xlfn._xlws.FILTER(C2:C10000,C2:C10000<>""),Ref!A:A,Ref!B:B)} -> HAR00344 | C2: {=_xlfn._xlws.FILTER('Paste DP'!A2:A10000&"",'Paste DP'!F2:F10000=A2:A10000<>"","")} -> Sean Gray | D2: {=IF(_xlfn._xlws.FILTER('Paste DP'!H2:H10000,'Paste DP'!F2:F10000=A2:A10000<>"","")="","",_xlfn._xlws.FILTER('Paste DP'!H2:H10000,'Paste DP'!F2:F10000=A2:A10000<>"",""))} -> 46191 | E2: {=MID(_xlfn._xlws.FILTER('Paste DP'!J2:J10000&"",'Paste DP'!F2:F10000=A2:A10000<>"",""),5,4)} -> 2608 | F2: {=_xlfn.XLOOKUP(_xlfn._xlws.FILTER(I2:I10000,I2:I10000<>""),Ref!G:G,Ref!H:H)} -> 4 | G2: {=_xlfn.XLOOKUP(_xlfn._xlws.FILTER(I2:I10000,I2:I10000<>""),Ref!G:G,Ref!I:I)} -> LA | H2: {=_xlfn.XLOOKUP(_xlfn._xlws.FILTER(I2:I10000,I2:I10000<>""),Ref!G:G,Ref!F:F)} -> 00408 | I2: {=_xlfn.IFNA(_xlfn.TEXTAFTER(_xlfn._xlws.FILTER('Paste DP'!K2:K10000&"",'Paste DP'!F2:F10000=A2:A10000<>"",""),"- "),_xlfn._xlws.FILTER('Paste DP'!K2:K10000&"",'Paste DP'!F2:F10000=A2:A10000<>"",""))} -> Structural Steel: Level bases and straighten structural steel | J2: {=_xlfn._xlws.FILTER('Paste DP'!P2:P10000&"",'Paste DP'!F2:F10000=A2:A10000<>"","")} -> 8.03 | K2: {=IF(WEEKDAY(_xlfn._xlws.FILTER(D2:D10000, D2:D10000<>""), 2) > 5, _xlfn.XLOOKUP(_xlfn._xlws.FILTER(C2:C10000, C2:C10000<>""), Ref!A:A, Ref!D:D), _xlfn.XLOOKUP(_xlfn._xlws.FILTER(C2:C10000, C2:C10000<>""), Ref!A:A, Ref!C:C))} -> 58.25 | L2: {=_xlfn.XLOOKUP(_xlfn._xlws.FILTER(C2:C10000,C2:C10000<>""),Ref!A:A,Ref!E:E)} -> N-T | M2: {=_xlfn._xlws.FILTER(IFERROR(J2:J10000*K2:K10000,"CHECK"),C2:C10000<>"")} -> 467.7475
A3: 5862 | B3: HAR00343 | C3: Martin Fischer | D3: 46191 | E3: 2608 | F3: 4 | G3: LA | H3: 00408 | I3: Structural Steel: Level bases and straighten structural steel | J3: 7.72 | K3: 58.25 | L3: N-T | M3: 449.69
A4: 5857 | B4: HAR00126 | C4: Lyric Kereopa | D4: 46190 | E4: 2608 | F4: 8 | G4: LA | H4: 00824 | I4: Internal Linings/ Finishes: Install Cement Sheet | J4: 8 | K4: 53.2 | L4: N-T | M4: 425.6
A5: 5859 | B5: HAR00343 | C5: Martin Fischer | D5: 46190 | E5: 2608 | F5: 5 | G5: LA | H5: 00503 | I5: Framing: Frame Installation | J5: 8.08 | K5: 58.25 | L5: N-T | M5: 470.66
A6: 5861 | B6: HAR00344 | C6: Sean Gray | D6: 46190 | E6: 2608 | F6: 4 | G6: LA | H6: 00408 | I6: Structural Steel: Level bases and straighten structural steel | J6: 8.07 | K6: 58.25 | L6: N-T | M6: 470.0775
A7: 5853 | B7: HAR00343 | C7: Martin Fischer | D7: 46189 | E7: 2608 | F7: 6 | G7: LA | H7: 00606 | I7: Floor Structure: Install Structflor | J7: 8 | K7: 58.25 | L7: N-T | M7: 466
A8: 5853 | B8: HAR00343 | C8: Martin Fischer | D8: 46189 | E8: 2608 | F8: 5 | G8: LA | H8: 00503 | I8: Framing: Frame Installation | K8: 58.25 | L8: N-T | M8: CHECK
A9: 5852 | B9: HAR00344 | C9: Sean Gray | D9: 46189 | E9: Abse | F9: 0 | G9: 0 | H9: 0 | I9: ABSENT | J9: 7.6 | K9: 58.25 | L9: N-T | M9: 442.7
A10: 5858 | B10: HAR00126 | C10: Lyric Kereopa | D10: 46188 | E10: 2608 | F10: 5 | G10: LA | H10: 00503 | I10: Framing: Frame Installation | J10: 8 | K10: 53.2 | L10: N-T | M10: 425.6
A11: 5851 | B11: HAR00344 | C11: Sean Gray | D11: 46188 | E11: Abse | F11: 0 | G11: 0 | H11: 0 | I11: ABSENT | J11: 7.6 | K11: 58.25 | L11: N-T | M11: 442.7
A12: 5839 | B12: HAR00126 | C12: Lyric Kereopa | D12: 46188 | E12: 2608 | F12: 6 | G12: LA | H12: 00603 | I12: Floor Structure: Install Kingspan (inc. cutting) | J12: 8 | K12: 53.2 | L12: N-T | M12: 425.6
A13: 5841 | B13: HAR00343 | C13: Martin Fischer | D13: 46188 | E13: 2608 | F13: 6 | G13: LA | H13: 00603 | I13: Floor Structure: Install Kingspan (inc. cutting) | J13: 8 | K13: 58.25 | L13: N-T | M13: 466
A14: 5838 | B14: HAR00126 | C14: Lyric Kereopa | D14: 46185 | E14: 2608 | F14: 6 | G14: LA | H14: 00606 | I14: Floor Structure: Install Structflor | J14: 7.5 | K14: 53.2 | L14: N-T | M14: 399
A15: 5832 | B15: HAR00343 | C15: Martin Fischer | D15: 46185 | E15: 2608 | F15: 6 | G15: LA | H15: 00606 | I15: Floor Structure: Install Structflor | J15: 8 | K15: 58.25 | L15: N-T | M15: 466
A16: 5835 | B16: HAR00344 | C16: Sean Gray | D16: 46185 | E16: 2608 | F16: 6 | G16: LA | H16: 00606 | I16: Floor Structure: Install Structflor | J16: 8.15 | K16: 58.25 | L16: N-T | M16: 474.7375
A17: 5826 | B17: HAR00126 | C17: Lyric Kereopa | D17: 46184 | E17: 2608 | F17: 6 | G17: LA | H17: 00606 | I17: Floor Structure: Install Structflor | J17: 8 | K17: 53.2 | L17: N-T | M17: 425.6
A18: 5824 | B18: HAR00343 | C18: Martin Fischer | D18: 46184 | E18: 2608 | F18: 6 | G18: LA | H18: 00606 | I18: Floor Structure: Install Structflor | J18: 7.53 | K18: 58.25 | L18: N-T | M18: 438.6225
A19: 5825 | B19: HAR00344 | C19: Sean Gray | D19: 46184 | E19: 2608 | F19: 6 | G19: LA | H19: 00606 | I19: Floor Structure: Install Structflor | J19: 8.25 | K19: 58.25 | L19: N-T | M19: 480.5625
A20: 5820 | B20: HAR00126 | C20: Lyric Kereopa | D20: 46183 | E20: 2608 | F20: 6 | G20: LA | H20: 00603 | I20: Floor Structure: Install Kingspan (inc. cutting) | J20: 7.5 | K20: 53.2 | L20: N-T | M20: 399
A21: 5823 | B21: HAR00343 | C21: Martin Fischer | D21: 46183 | E21: 2608 | F21: 4 | G21: LA | H21: 00408 | I21: Structural Steel: Level bases and straighten structural steel | J21: 8 | K21: 58.25 | L21: N-T | M21: 466
A22: 5811 | B22: HAR00344 | C22: Sean Gray | D22: 46183 | E22: 2608 | F22: 6 | G22: LA | H22: 00603 | I22: Floor Structure: Install Kingspan (inc. cutting) | J22: 8 | K22: 58.25 | L22: N-T | M22: 466
A23: 5819 | B23: HAR00126 | C23: Lyric Kereopa | D23: 46182 | E23: 2608 | F23: 6 | G23: LA | H23: 00603 | I23: Floor Structure: Install Kingspan (inc. cutting) | J23: 8 | K23: 53.2 | L23: N-T | M23: 425.6
A24: 5810 | B24: HAR00343 | C24: Martin Fischer | D24: 46182 | E24: 2608 | F24: 4 | G24: LA | H24: 00408 | I24: Structural Steel: Level bases and straighten structural steel | J24: 7.6 | K24: 58.25 | L24: N-T | M24: 442.7
A25: 5810 | B25: HAR00343 | C25: Martin Fischer | D25: 46182 | E25: Abse | F25: 0 | G25: 0 | H25: 0 | I25: ABSENT | K25: 58.25 | L25: N-T | M25: CHECK
A26: 5809 | B26: HAR00344 | C26: Sean Gray | D26: 46182 | E26: 2608 | F26: 4 | G26: LA | H26: 00408 | I26: Structural Steel: Level bases and straighten structural steel | J26: 8 | K26: 58.25 | L26: N-T | M26: 466
A27: 5818 | B27: HAR00126 | C27: Lyric Kereopa | D27: 46178 | E27: 2608 | F27: 4 | G27: LA | H27: 00407 | I27: Structural Steel: Paint Base Labour | J27: 8 | K27: 53.2 | L27: N-T | M27: 425.6
A28: 5801 | B28: HAR00344 | C28: Sean Gray | D28: 46178 | E28: 0000 | F28: 4 | G28: LA | H28: 00406 | I28: Structural Steel: Structural Steel external coating paint | J28: 8.2 | K28: 58.25 | L28: N-T | M28: 477.65
A29: 5802 | B29: HAR00343 | C29: Martin Fischer | D29: 46178 | E29: 2608 | F29: 4 | G29: LA | H29: 00407 | I29: Structural Steel: Paint Base Labour | J29: 8 | K29: 58.25 | L29: N-T | M29: 466
A30: 5817 | B30: HAR00126 | C30: Lyric Kereopa | D30: 46177 | E30: 2608 | F30: 17 | G30: LA | H30: 01704 | I30: Prep modules for Transport: Split pods and Transport Prep | J30: 8 | K30: 53.2 | L30: N-T | M30: 425.6
A31: 5800 | B31: HAR00343 | C31: Martin Fischer | D31: 46177 | E31: 2608 | F31: 4 | G31: LA | H31: 00407 | I31: Structural Steel: Paint Base Labour | J31: 8 | K31: 58.25 | L31: N-T | M31: 466
A32: 5798 | B32: HAR00344 | C32: Sean Gray | D32: 46177 | E32: 0000 | F32: 19 | G32: LA | H32: 01906 | I32: Building Install: Onsite Commissioning Works | J32: 8 | K32: 58.25 | L32: N-T | M32: 466
A33: 5797 | B33: HAR00344 | C33: Sean Gray | D33: 46176 | E33: 0000 | F33: 19 | G33: LA | H33: 01906 | I33: Building Install: Onsite Commissioning Works | J33: 7.6 | K33: 58.25 | L33: N-T | M33: 442.7
A34: 5795 | B34: HAR00126 | C34: Lyric Kereopa | D34: 46176 | E34: 0000 | F34: 19 | G34: LA | H34: 01906 | I34: Building Install: Onsite Commissioning Works | J34: 7.6 | K34: 53.2 | L34: N-T | M34: 404.32
A35: 5794 | B35: HAR00343 | C35: Martin Fischer | D35: 46176 | E35: 0000 | F35: 19 | G35: LA | H35: 01907 | I35: Building Install: On-site Clean | J35: 7.6 | K35: 58.25 | L35: N-T | M35: 442.7
A36: 5793 | B36: HAR00343 | C36: Martin Fischer | D36: 46175 | E36: 0000 | F36: 19 | G36: LA | H36: 01907 | I36: Building Install: On-site Clean | J36: 7.5 | K36: 58.25 | L36: N-T | M36: 436.875
A37: 5788 | B37: HAR00344 | C37: Sean Gray | D37: 46175 | E37: 0000 | F37: 19 | G37: LA | H37: 01907 | I37: Building Install: On-site Clean | J37: 7.57 | K37: 58.25 | L37: N-T | M37: 440.9525
... A45: 5764 | B45: HAR00344 | C45: Sean Gray | D45: 46168 | E45: 2535 | F45: 17 | G45: LA | H45: 01704 | I45: Prep modules for Transport: Split pods and Transport Prep | J45: 8 | K45: 58.25 | L45: N-T | M45: 466
A46: 5764 | B46: HAR00344 | C46: Sean Gray | D46: 46168 | E46: 2608 | F46: 13 | G46: LA | H46: 01305 | I46: Insulation: Insulation Installation | K46: 58.25 | L46: N-T | M46: CHECK
A47: 5764 | B47: HAR00344 | C47: Sean Gray | D47: 46168 | E47: 0000 | F47: 8 | G47: LA | H47: 00845 | I47: Internal Linings/ Finishes: Birch Ply Prep Work (not install) | K47: 58.25 | L47: N-T | M47: CHECK
...

Sheet Ref
A1: Accounting System Code | F1: Reference Code Column | G1: Reference Description
A2: Name | B2: Code | C2: Rate | D2: OT Rate | E2: Tax Code | F2: 001 | G2: Preliminaries
A3: Lyric Kereopa | B3: HAR00126 | C3: 53.2 | D3: =C3*1.5 -> 79.8 | E3: N-T | F3: 00101 | G3: Preliminaries: Architect | H3: 1 | I3: LA
A4: Matt Cornell | B4: HAR00183 | C4: 50.4 | D4: =C4*1.5 -> 75.6 | E4: N-T | F4: 00102 | G4: Preliminaries: Structural Engineering | H4: 1 | I4: LA
A5: Ray Po-Ching | B5: HAR00284 | C5: 46.2 | D5: =C5*1.5 -> 69.3 | E5: N-T | F5: 00103 | G5: Preliminaries: Miscellaneous Items | H5: 1 | I5: LA
A6: Martin Fischer | B6: HAR00343 | C6: 58.25 | D6: =C6*1.5 -> 87.375 | E6: N-T | F6: 00104 | G6: Preliminaries: Consumables (drill bits, blades, discs) | H6: 1 | I6: LA
A7: Sean Gray | B7: HAR00344 | C7: 58.25 | D7: =C7*1.5 -> 87.375 | E7: N-T | F7: 00105 | G7: Preliminaries: Fixings & Packers (glue, screws etc.) | H7: 1 | I7: LA
A8: Heng kem Lay | B8: HAR00220 | C8: 33.6 | D8: =C8*1.5 -> 50.4 | E8: N-T | F8: 00106 | G8: Preliminaries: Miscellaneous Labour | H8: 1 | I8: LA
A9: Steve Dcosta | B9: HAR00285 | C9: 50.4 | D9: =C9*1.5 -> 75.6 | E9: N-T | F9: 00107 | G9: Preliminaries: Material Pickup/Delivery | H9: 1 | I9: LA
A10: robert kardum | B10: HAR00185 | C10: 56 | D10: =C10*1.5 -> 84 | E10: N-T | F10: 00108 | G10: Preliminaries: Misc. Timber Supply | H10: 1 | I10: LA
F11: 00109 | G11: Preliminaries: Packers | H11: 1 | I11: LA
F12: 00110 | G12: Preliminaries: Light Towers | H12: 1 | I12: LA
F13: 00111 | G13: Preliminaries: Skip bin | H13: 1 | I13: LA
F14: 00112 | G14: Preliminaries: Generator | H14: 1 | I14: LA
F15: 00113 | G15: Prelimonaries: Scaffold Hire onsite | H15: 1 | I15: LA
F16: 00114 | G16: Preliminaries: Equipment Hire onsite | H16: 1 | I16: LA
F17: 00115 | G17: Preliminaries: site safety (fence) | H17: 1 | I17: LA
F18: 00116 | G18: Preliminaries: onsite toilet + servicing | H18: 1 | I18: LA
F19: 00117 | G19: Preliminaries: Project Management Fees | H19: 1 | I19: LA
F20: 00118 | G20: Preliminaries: Render | H20: 1 | I20: LA
F21: 002 | G21: Site Investigation | H21: Set | I21: LA
F22: 00201 | G22: Site Investigation: Feature and Levels Survey | H22: 2 | I22: LA
F23: 00202 | G23: Site Investigation: Underground Services Check | H23: 2 | I23: LA
F24: 00203 | G24: Site Investigation: Soil Report | H24: 2 | I24: LA
F25: 00204 | G25: Site Investigation: Exposing services | H25: 2 | I25: LA
F26: 00205 | G26: Site Investigation: Dilapidation Report | H26: 2 | I26: LA
F27: 003 | G27: Building Permit | H27: Set | I27: LA
F28: 00301 | G28: Building Permit: Building Surveyor Fees | H28: 3 | I28: LA
F29: 00302 | G29: Building Permit: Energy Report | H29: 3 | I29: LA
F30: 00303 | G30: Building Permit: BAL Report | H30: 3 | I30: LA
F31: 00304 | G31: Building Permit: Lodging Fees | H31: 3 | I31: LA
F32: 00305 | G32: Building Permit: Civil Engineer | H32: 3 | I32: LA
F33: 00306 | G33: Building Permit: Mechanical Engineer | H33: 3 | I33: LA
F34: 00307 | G34: Building Permit: Fire Engineer | H34: 3 | I34: LA
F35: 00308 | G35: Building Permit: Hydraulic Engineer | H35: 3 | I35: LA
F36: 00309 | G36: Building Permit: DDA consultant | H36: 3 | I36: LA
F37: 00310 | G37: Building Permit: Lighting Consultant | H37: 3 | I37: LA
F38: 00311 | G38: Building Permit: Electrical Engineer | H38: 3 | I38: LA
F39: 00312 | G39: Building Permit: Facade Performance Solution | H39: 3 | I39: LA
F40: 004 | G40: Structural Steel | H40: Set | I40: LA
...
